Workbook

Sheet stamgegevens
A1: Stamgegevens
A2: Administratiecode | B2: 0000
A3: Naam bedrijf | B3: CREATENEW WORK
A4: CAO | B4: VUL IN
A5: Loonjaar | B5: 2026
A6: Grote/kleine werkgever | B6: Klein
A7: Sector | B7: 52
A8: WGA grote werkgever | B8: 1.97
A9: ZW-Flex grote werkgever | B9: 3.91
A10: WGA kleine werkgever | B10: 2.68
A11: ZW-Flex kleine werkgever | B11: 3.71
A12: WAO/WIA basispremie (Aof) grote werkgever | B12: 7.61
A13: WAO/WIA basispremie (Aof) kleine werkgever | B13: 6.26
A14: Eigen risicodrager ZW-Flex | B14: nee
A17: Standaard reserveringen | B17: =IF(B4="NBBU","met beding 1+2","met beding A") -> met beding A | C17: =IF(B4="NBBU","zonder beding 3+4","zonder beding B+C") -> zonder beding B+C | D17: =IF(B4="NBBU","zonder beding 1+2","zonder beding A") -> zonder beding A | F17: Voorzieningen (opslagen) | G17: administratief | H17: administratief | I17: administratief | J17: techn./industrieel | K17: techn./industrieel | L17: techn./industrieel
A18: Feestdagen | B18: =(J36/J37)*100 -> 2.6086957 | C18: 0 | D18: 0 | G18: =B17 -> met beding A | H18: =C17 -> zonder beding B+C | I18: =D17 -> zonder beding A | J18: =B17 -> met beding A | K18: =C17 -> zonder beding B+C | L18: =D17 -> zonder beding A
A19: Vakantiedagen regulier | B19: =(J35/J37)*100 -> 10.869565 | C19: =(J35/J37)*100 -> 10.869565 | D19: =(J35/J37)*100 -> 10.869565 | F19: Duurzame inzetbaarheid | G19: 0 | H19: 0 | I19: 0 | J19: 0 | K19: 0 | L19: 0
A20: Vakantiedagen vakantiewerk | B20: 8.33 | C20: 8.33 | D20: 8.33 | F20: Sociaal Fonds | G20: 0.2 | H20: 0 | I20: 0.2 | J20: 0.2 | K20: 0 | L20: 0.2
A21: Vakantiegeld | B21: 8.33 | C21: 8.33 | D21: 8.33 | F21: Arbeidsongeschiktheid | G21: 0 | H21: 0 | I21: 0 | J21: 0 | K21: 0 | L21: 0
F22: Contractverplichting/leegloop | G22: 0 | H22: 0 | I22: 0 | J22: 0 | K22: 0 | L22: 0
F23: Reservering KV/FD contracten | G23: 0.6 | H23: 0.6 | I23: 0.6 | J23: 0.6 | K23: 0.6 | L23: 0.6
A24: Sociale verzekeringen | B24: werknemer | C24: werkgever | D24: totaal | F24: Transitievergoeding | G24: 0 | H24: 0 | I24: 0 | J24: 0 | K24: 0 | L24: 0
A25: Aanvullende ziektewet (AZV) administratief | B25: 0.3 | C25: 1.9 | D25: =SUM(B25:C25) -> 2.2 | F25: Organisatiekosten | G25: 0 | H25: 0 | I25: 0 | J25: 0 | K25: 0 | L25: 0
A26: Aanvullende ziektewet (AZV) technisch | B26: 0.7 | C26: 3.26 | D26: =SUM(B26:C26) -> 3.96 | F26: Overige opslagen 1 | G26: 0 | H26: 0 | I26: 0 | J26: 0 | K26: 0 | L26: 0
A27: Zorgverzekeringswet (ZVW) | B27: 0 | C27: 6.1 | D27: =SUM(B27:C27) -> 6.1 | F27: Overige opslagen 2 | G27: 0 | H27: 0 | I27: 0 | J27: 0 | K27: 0 | L27: 0
A28: Gedifferentieerde premie WhK (WGA) | B28: =IF(B6="klein",(B10/2),(B8/2)) -> 1.34 | C28: =IF(B6="klein",(B10/2),(B8/2)) -> 1.34 | D28: =SUM(B28:C28) -> 2.68 | F28: Overige opslagen 3 | G28: 0 | H28: 0 | I28: 0 | J28: 0 | K28: 0 | L28: 0
A29: =IF(B14="ja","Gedifferentieerde premie WhK (ZW-Flex) ERD","Gedifferentieerde premie WhK (ZW-Flex)") -> Gedifferentieerde premie WhK (ZW-Flex) | B29: 0 | C29: =IF(B6="klein",B11,B9) -> 3.71 | D29: =SUM(B29:C29) -> 3.71 | F29: Overige opslagen 4 | G29: 0 | H29: 0 | I29: 0 | J29: 0 | K29: 0 | L29: 0
A30: WW (Awf) | B30: 0 | C30: 7.74 | D30: =SUM(B30:C30) -> 7.74 | F30: Totaal | G30: =SUM(G19:G29) -> 0.8 | H30: =SUM(H19:H29) -> 0.6 | I30: =SUM(I19:I29) -> 0.8 | J30: =SUM(J19:J29) -> 0.8 | K30: =SUM(K19:K29) -> 0.6 | L30: =SUM(L19:L29) -> 0.8
A31: WAO/WIA basispremie (Aof) | B31: 0 | C31: =IF(B6="klein",B13,B12) -> 6.26 | D31: =SUM(B31:C31) -> 6.26
A32: Wko (wet kinderopvang) | B32: 0 | C32: 0.5 | D32: =SUM(B32:C32) -> 0.5
A33: PAWW | B33: 0 | C33: 0.1 | D33: =SUM(B33:C33) -> 0.1 | F33: Standaard werkbare dagen
F34: Bruto werkbare dagen | J34: 261
F35: Vakantiedagen | J35: 25
A36: Pensioenen | B36: werknemer | C36: werkgever | D36: totaal | F36: Feestdagen | J36: 6
A37: Stipp-pensioen * | B37: 7.95 | C37: 15.9 | D37: =SUM(B37:C37) -> 23.85 | F37: Netto werkbare dagen | J37: =J34-J35-J36 -> 230
A38: Gemiddeld uurloon voor berekening kostprijs | D38: 25
A39: Franchise | D39: 8.9
A40: Compensatiefactor pensioen | D40: 0.853
A43: Opslag sociale lasten
A44: Administratief met beding | B44: =C25+C27+C28+C29+C30+C31+C32+C33+kostprijzen!B48 -> 37.8896
...

Sheet kostprijzen
A1: =CONCATENATE(stamgegevens!B3," ",stamgegevens!B5) -> CREATENEW WORK 2026 | B1: Administratief | E1: Administratief | H1: Administratief | K1: Techn./Industrieel | N1: Techn./Industrieel | Q1: Techn./Industrieel
B2: =stamgegevens!$B$17 -> met beding A | E2: =stamgegevens!$C$17 -> zonder beding B+C | H2: =stamgegevens!$D$17 -> zonder beding A | K2: =stamgegevens!$B$17 -> met beding A | N2: =stamgegevens!$C$17 -> zonder beding B+C | Q2: =stamgegevens!$D$17 -> zonder beding A
A5: Berekening reserveringen
A6: Bruto werkbare dagen | B6: =stamgegevens!$J$34 -> 261 | E6: =stamgegevens!$J$34 -> 261 | H6: =stamgegevens!$J$34 -> 261 | K6: =stamgegevens!$J$34 -> 261 | N6: =stamgegevens!$J$34 -> 261 | Q6: =stamgegevens!$J$34 -> 261
A7: Vakantiedagen | B7: =stamgegevens!$J$35 -> 25 | C7: =B7/B10 -> 0.10869565 | E7: =stamgegevens!$J$35 -> 25 | F7: =E7/E10 -> 0.10869565 | H7: =stamgegevens!$J$35 -> 25 | I7: =H7/H10 -> 0.10869565 | K7: =stamgegevens!$J$35 -> 25 | L7: =K7/K10 -> 0.10869565 | N7: =stamgegevens!$J$35 -> 25 | O7: =N7/N10 -> 0.10869565 | Q7: =stamgegevens!$J$35 -> 25 | R7: =Q7/Q10 -> 0.10869565
A8: Feestdagen | B8: =stamgegevens!$J$36 -> 6 | C8: =B8/B10 -> 0.026086957 | E8: =stamgegevens!$J$36 -> 6 | F8: =E8/E10 -> 0.026086957 | H8: =stamgegevens!$J$36 -> 6 | I8: =H8/H10 -> 0.026086957 | K8: =stamgegevens!$J$36 -> 6 | L8: =K8/K10 -> 0.026086957 | N8: =stamgegevens!$J$36 -> 6 | O8: =N8/N10 -> 0.026086957 | Q8: =stamgegevens!$J$36 -> 6 | R8: =Q8/Q10 -> 0.026086957
A9: ATV-dagen | B9: 0 | C9: =B9/B10 -> 0 | E9: 0 | F9: =E9/E10 -> 0 | H9: 0 | I9: =H9/H10 -> 0 | K9: 0 | L9: =K9/K10 -> 0 | N9: 0 | O9: =N9/N10 -> 0 | Q9: 0 | R9: =Q9/Q10 -> 0
A10: Netto werkbare dagen | B10: =B6-B7-B8-B9 -> 230 | E10: =E6-E7-E8-E9 -> 230 | H10: =H6-H7-H8-H9 -> 230 | K10: =K6-K7-K8-K9 -> 230 | N10: =N6-N7-N8-N9 -> 230 | Q10: =Q6-Q7-Q8-Q9 -> 230
A12: Vakantiegeld | C12: 8 | F12: 8 | I12: 8 | L12: 8 | O12: 8 | R12: 8
A13: Percentage pensioenregeling werkgever | C13: 0 | F13: 0 | I13: 0 | L13: 0 | O13: 0 | R13: 0
A14: Percentage compensatie pensioenregeling | C14: =IF(C13>stamgegevens!$C$37,kostprijzen!C13-stamgegevens!$C$37,0) -> 0 | F14: =IF(F13>stamgegevens!$C$37,kostprijzen!F13-stamgegevens!$C$37,0) -> 0 | I14: =IF(I13>stamgegevens!$C$37,kostprijzen!I13-stamgegevens!$C$37,0) -> 0 | L14: =IF(L13>stamgegevens!$C$37,kostprijzen!L13-stamgegevens!$C$37,0) -> 0 | O14: =IF(O13>stamgegevens!$C$37,kostprijzen!O13-stamgegevens!$C$37,0) -> 0 | R14: =IF(R13>stamgegevens!$C$37,kostprijzen!R13-stamgegevens!$C$37,0) -> 0
A16: Basis | C16: 100 | F16: 100 | I16: 100 | L16: 100 | O16: 100 | R16: 100
A18: Reserveringen I
A19: Feestdagen | B19: =C8*100 -> 2.6086957 | E19: =F8*100 -> 2.6086957 | H19: =I8*100 -> 2.6086957 | K19: =L8*100 -> 2.6086957 | N19: =O8*100 -> 2.6086957 | Q19: =R8*100 -> 2.6086957
A20: Vakantiedagen | B20: =C7*100 -> 10.869565 | E20: =F7*100 -> 10.869565 | H20: =I7*100 -> 10.869565 | K20: =L7*100 -> 10.869565 | N20: =O7*100 -> 10.869565 | Q20: =R7*100 -> 10.869565
A21: ATV | B21: =C9*100 -> 0 | E21: =F9*100 -> 0 | H21: =I9*100 -> 0 | K21: =L9*100 -> 0 | N21: =O9*100 -> 0 | Q21: =R9*100 -> 0
A22: Extra reservering | B22: 0 | E22: 0 | H22: 0 | K22: 0 | N22: 0 | Q22: 0
A23: Totaal | B23: =SUM(B19:B22) -> 13.478261 | C23: =(B23/100)*C16 -> 13.478261 | E23: =SUM(E19:E22) -> 13.478261 | F23: =(E23/100)*F16 -> 13.478261 | H23: =SUM(H19:H22) -> 13.478261 | I23: =(H23/100)*I16 -> 13.478261 | K23: =SUM(K19:K22) -> 13.478261 | L23: =(K23/100)*L16 -> 13.478261 | N23: =SUM(N19:N22) -> 13.478261 | O23: =(N23/100)*O16 -> 13.478261 | Q23: =SUM(Q19:Q22) -> 13.478261 | R23: =(Q23/100)*R16 -> 13.478261
C24: =C16+C23 -> 113.47826 | F24: =F16+F23 -> 113.47826 | I24: =I16+I23 -> 113.47826 | L24: =L16+L23 -> 113.47826 | O24: =O16+O23 -> 113.47826 | R24: =R16+R23 -> 113.47826
A25: Reserveringen II
A26: Vakantiegeld | B26: =C12 -> 8 | E26: =F12 -> 8 | H26: =I12 -> 8 | K26: =L12 -> 8 | N26: =O12 -> 8 | Q26: =R12 -> 8
A27: IKB | B27: 0 | E27: 0 | H27: 0 | K27: 0 | N27: 0 | Q27: 0
A28: Eindjeaarsuitkering | B28: 0 | E28: 0 | H28: 0 | K28: 0 | N28: 0 | Q28: 0
A29: Totaal | B29: =SUM(B26:B28) -> 8 | C29: =(B29/100)*C24 -> 9.0782609 | E29: =SUM(E26:E28) -> 8 | F29: =(E29/100)*F24 -> 9.0782609 | H29: =SUM(H26:H28) -> 8 | I29: =(H29/100)*I24 -> 9.0782609 | K29: =SUM(K26:K28) -> 8 | L29: =(K29/100)*L24 -> 9.0782609 | N29: =SUM(N26:N28) -> 8 | O29: =(N29/100)*O24 -> 9.0782609 | Q29: =SUM(Q26:Q28) -> 8 | R29: =(Q29/100)*R24 -> 9.0782609
C30: =C24+C29 -> 122.55652 | F30: =F24+F29 -> 122.55652 | I30: =I24+I29 -> 122.55652 | L30: =L24+L29 -> 122.55652 | O30: =O24+O29 -> 122.55652 | R30: =R24+R29 -> 122.55652
A31: CAO-reserveringen
A32: Compensatie pensioenregeling | B32: =C14*stamgegevens!$D$40 -> 0 | E32: =F14*stamgegevens!$D$40 -> 0 | H32: =I14*stamgegevens!$D$40 -> 0 | K32: =L14*stamgegevens!$D$40 -> 0 | N32: =O14*stamgegevens!$D$40 -> 0 | Q32: =R14*stamgegevens!$D$40 -> 0
A33: - | B33: 0 | E33: 0 | H33: 0 | K33: 0 | N33: 0 | Q33: 0
A34: - | B34: 0 | E34: 0 | H34: 0 | K34: 0 | N34: 0 | Q34: 0
B35: =SUM(B31:B34) -> 0 | C35: =(B35/100)*C30 -> 0 | E35: =SUM(E31:E34) -> 0 | F35: =(E35/100)*F30 -> 0 | H35: =SUM(H31:H34) -> 0 | I35: =(H35/100)*I30 -> 0 | K35: =SUM(K31:K34) -> 0 | L35: =(K35/100)*L30 -> 0 | N35: =SUM(N31:N34) -> 0 | O35: =(N35/100)*O30 -> 0 | Q35: =SUM(Q31:Q34) -> 0 | R35: =(Q35/100)*R30 -> 0
C36: =C30+C35 -> 122.55652 | F36: =F30+F35 -> 122.55652 | I36: =I30+I35 -> 122.55652 | L36: =L30+L35 -> 122.55652 | O36: =O30+O35 -> 122.55652 | R36: =R30+R35 -> 122.55652
A37: Sociale verzekeringen
A38: Aanvullende ziektewet (AZV) | B38: =stamgegevens!$C$25 -> 1.9 | E38: 0 | H38: =stamgegevens!$C$25 -> 1.9 | K38: =stamgegevens!$C$26 -> 3.26 | N38: 0 | Q38: =stamgegevens!$C$26 -> 3.26
A39: Zorgverzekeringswet (ZVW) | B39: =stamgegevens!$C$27 -> 6.1 | E39: =stamgegevens!$C$27 -> 6.1 | H39: =stamgegevens!$C$27 -> 6.1 | K39: =stamgegevens!$C$27 -> 6.1 | N39: =stamgegevens!$C$27 -> 6.1 | Q39: =stamgegevens!$C$27 -> 6.1
A40: Gedifferentieerde premie WhK (WGA) | B40: =stamgegevens!$C$28 -> 1.34 | E40: =stamgegevens!$C$28 -> 1.34 | H40: =stamgegevens!$C$28 -> 1.34 | K40: =stamgegevens!$C$28 -> 1.34 | N40: =stamgegevens!$C$28 -> 1.34 | Q40: =stamgegevens!$C$28 -> 1.34
A41: =IF(C24="ERD","Gedifferentieerde premie WhK (ZW-Flex) ERD","Gedifferentieerde premie WhK (ZW-Flex)") -> Gedifferentieerde premie WhK (ZW-Flex) | B41: =stamgegevens!$C$29 -> 3.71 | E41: =stamgegevens!$C$29 -> 3.71 | H41: =stamgegevens!$C$29 -> 3.71 | K41: =stamgegevens!$C$29 -> 3.71 | N41: =stamgegevens!$C$29 -> 3.71 | Q41: =stamgegevens!$C$29 -> 3.71
A42: WW (Awf) | B42: =stamgegevens!$C$30 -> 7.74 | E42: =stamgegevens!$C$30 -> 7.74 | H42: =stamgegevens!$C$30 -> 7.74 | K42: =stamgegevens!$C$30 -> 7.74 | N42: =stamgegevens!$C$30 -> 7.74 | Q42: =stamgegevens!$C$30 -> 7.74
A43: WAO/WIA basispremie (Aof) | B43: =stamgegevens!$C$31 -> 6.26 | E43: =stamgegevens!$C$31 -> 6.26 | H43: =stamgegevens!$C$31 -> 6.26 | K43: =stamgegevens!$C$31 -> 6.26 | N43: =stamgegevens!$C$31 -> 6.26 | Q43: =stamgegevens!$C$31 -> 6.26
A44: Wko | B44: =stamgegevens!$C$32 -> 0.5 | E44: =stamgegevens!$C$32 -> 0.5 | H44: =stamgegevens!$C$32 -> 0.5 | K44: =stamgegevens!$C$32 -> 0.5 | N44: =stamgegevens!$C$32 -> 0.5 | Q44: =stamgegevens!$C$32 -> 0.5
A45: PAWW | B45: =stamgegevens!$C$33 -> 0.1 | E45: =stamgegevens!$C$33 -> 0.1 | H45: =stamgegevens!$C$33 -> 0.1 | K45: =stamgegevens!$C$33 -> 0.1 | N45: =stamgegevens!$C$33 -> 0.1 | Q45: =stamgegevens!$C$33 -> 0.1
...
